Workbook
Name GPU_Capex: Inputs!$C$5
Name GPU_Life: Inputs!$C$6
Name GPU_Salvage: Inputs!$C$7
Name GPU_Power_Load_W: Inputs!$C$8
Name GPU_Power_Idle_W: Inputs!$C$9
Name PUE: Inputs!$C$10
Name Aux_Power_W: Inputs!$C$11
Name Avail: Inputs!$C$12
Name Rack_Capex: Inputs!$C$15
Name DC_Capex: Inputs!$C$16
Name OandM: Inputs!$C$17
Name GridFee_per_kWyr: Inputs!$C$18
Name WACC: Inputs!$C$19
Name Tax: Inputs!$C$20
Name Rev_per_hr: Inputs!$C$23
Name Util: Inputs!$C$24
Name Interrupt_Haircut: Inputs!$C$25
Name Floor_Price: Inputs!$C$26
Name Grid_Price: Inputs!$C$29
Name Curt_Price: Inputs!$C$30
Name Curt_Hr_Day: Inputs!$C$31
Name Curt_Days: Inputs!$C$32
Name PPA_Price: Inputs!$C$33
Name Carbon: Inputs!$C$34
Name Hrs_Daytime: Inputs!$C$37
Name Hrs_Curt: Inputs!$C$38
Name Fleet: Inputs!$C$39
Name Horizon: Inputs!$C$40
Name Curt_Threshold: Solar_Profile!$J$5
Name Total_Capex: GPU_Economics!$C$8
Name Fixed_Cost_GPU: GPU_Economics!$C$15
Name Load_kW: GPU_Economics!$C$19
Name Idle_kW: GPU_Economics!$C$20
Name Rev_Firm: GPU_Economics!$C$23
Name Rev_Interr: GPU_Economics!$C$24
Name EBITDA_A: Scenarios!$C$13
Name EBITDA_B: Scenarios!$D$13
Name EBITDA_C: Scenarios!$E$13
Name Idle_Hrs_C: Scenarios!$E$17
Name Hourly_EBITDA_A: Hourly_Model!$I$105
Name Hourly_EBITDA_B: Hourly_Model!$J$105
Name Hourly_EBITDA_C: Hourly_Model!$K$105

Sheet Cover
B2: Solar Écrêtement (curtailment) vs. H100 Idle Cost
B3: A financial-equilibrium model — Europe, daylight curtailment hours vs 24/7 GPU economics
B5: The question
B6: European solar farms increasingly experience écrêtement — curtailment driven by negative spot prices during midday peaks. At the same time, H100 GPUs cost ~$30–40k each and depreciate whether or not they are running. Can we make money by stranding GPUs at solar sites and only powering them during the curtailment window, accepting idle hours the rest of the day? At what electricity price, curtailment window length, and GPU rental rate does the equilibrium tip?
B11: Model map
B12: Inputs | C12: All editable assumptions (yellow cells). Change these and everything recalculates.
B13: Solar_Profile | C13: Hourly solar capacity factor across the four seasons, with the curtailment window.
B14: Price_Curve | C14: Hourly spot price by season, anchored to country averages and midday troughs.
B15: GPU_Economics | C15: Per-GPU capex, depreciation, power draw, datacenter PUE, opex stack.
B16: Scenarios | C16: Three operating modes side-by-side: 24/7, daytime-only, curtailment-only.
B17: Hourly_Model | C17: Representative 96-hour year (4 seasons × 24h) scaled to 8,760h with hourly P&L.
B18: Equilibrium | C18: Break-even curves: at what electricity price / curtailment hours do the modes cross?
B19: Sensitivity | C19: Two-way tables: GPU price × rental rate, and curtailment hours × idle penalty.
B20: Country_Compare | C20: Germany, Spain, France, Netherlands, Italy, UK — negative-price hours and outcomes.
B21: Dashboard | C21: Single-page answer: payback, NPV, IRR, and the equilibrium electricity price.
B24: Color legend
C25: Input — edit me (yellow)
C26: Calculation (green)
C27: Cross-sheet link (blue)
C28: Favorable outcome
C29: Unfavorable outcome
B32: Methodology in one paragraph
B33: We model a single H100 (or a DGX-equivalent 8-GPU node) co-located at a European solar site that suffers curtailment. The plant offers electricity at the spot price during the curtailment window (often €0 or negative). Outside that window the GPU can either (a) buy grid power at retail and keep earning, or (b) sit idle. We compare 3 operating modes against the same capex stack. Revenue is benchmarked to H100 on-demand rental rates (a proxy for the value of FLOPs). The equilibrium is the electricity-price + curtailment-hours combination at which the curtailment-only mode equals 24/7 economics. All figures are in EUR; FX is held flat — this is a directional model, not a pricing sheet.

Sheet Inputs
B2: Master inputs — yellow cells drive every other sheet
B4: GPU Hardware (per H100)
B5: H100 capex (street price, EUR) | C5: 32000 | E5: Q4-2025 European street price for SXM5. Hopper has come off peak. Range €25k–€40k.
B6: Useful life (years) | C6: 4 | E6: NVIDIA suggests 5; aggressive Blackwell roadmap argues 3–4.
B7: Salvage value at end of life (% of capex) | C7: 0.1 | E7: Resale to crypto/CV inference shops. Bear case = 0%.
B8: GPU power draw, full load (W) | C8: 700 | E8: H100 SXM5 TDP.
B9: GPU power draw, idle (W) | C9: 90 | E9: Powered on, no kernels running.
B10: Datacenter PUE | C10: 1.2 | E10: Modern liquid-cooled colo at a solar site, no chiller round-trip.
B11: CPU/networking overhead allocated (W) | C11: 180 | E11: Per-GPU share of CPU, NIC, NVSwitch, fans.
B12: Hardware availability | C12: 0.97 | E12: After failures, RMA, planned maintenance.
B14: Site & Datacenter (per GPU allocation)
B15: Rack & networking capex per GPU (EUR) | C15: 4500 | E15: Share of DGX-class server, NVSwitch, top-of-rack.
B16: Modular datacenter capex per GPU (EUR) | C16: 3500 | E16: Container DC, cooling loop, transformer share, civils.
B17: Annual O&M per GPU (EUR) | C17: 1200 | E17: Maintenance, remote hands, monitoring, insurance.
B18: Grid connection fee per kW-yr (EUR) | C18: 90 | E18: Most curtailment sites already have the connection paid by the solar farm.
B19: Cost of capital (WACC) | C19: 0.1 | E19: Specialty infra; range 8–14%.
B20: Corporate tax rate | C20: 0.25 | E20: EU-blended.
B22: Revenue (H100 monetisation)
B23: Effective H100 hourly rental (EUR/h) | C23: 2.2 | E23: Realised price net of broker / utilisation discount. On-demand list ~€2.50–4.
B24: Utilisation when powered on | C24: 0.85 | E24: Fraction of powered hours sold.
B25: Revenue haircut for interruptible workloads | C25: 0.3 | E25: Discount applied because curtailment-only mode is non-firm capacity.
B26: Crypto/inference floor price (EUR/h) | C26: 0.4 | E26: Fallback when no AI tenant takes the hour.
B28: Electricity & curtailment regime
B29: Average grid retail price (EUR/MWh) | C29: 140 | E29: EU blended industrial 2025 estimate.
B30: Curtailment-window price (EUR/MWh) | C30: -15 | E30: Avg spot during écrêtement — often negative.
B31: Curtailment hours per day (peak season) | C31: 5 | E31: Hours/day with negative or sub-€10 prices in summer.
B32: Curtailment days per year | C32: 180 | E32: Days/year that exhibit the curtailment pattern.
B33: Behind-the-meter solar PPA (EUR/MWh) | C33: 25 | E33: Long-term PPA used outside curtailment window if BTM.
B34: Carbon credit value (EUR/MWh avoided) | C34: 0 | E34: Set >0 to credit displaced fossil generation.
B36: Scenario toggles
B37: Hours/day H100 powered on (daytime mode) | C37: 10 | E37: Daytime-only operating window.
B38: Hours/day H100 powered on (curtailment mode) | C38: 5 | E38: Curtailment-only operating window.
B39: Number of GPUs in fleet | C39: 1000 | E39: Used only for headline P&L on dashboard.
B40: Project horizon (years) | C40: 5 | E40: Used for NPV / IRR.

Sheet Solar_Profile
B2: Hourly solar capacity factor & curtailment window
B3: Representative day per season. Curtailment flag = 1 when capacity factor exceeds the threshold.
B5: Hour | C5: Winter CF | D5: Spring CF | E5: Summer CF | F5: Autumn CF | G5: Avg CF | H5: Curtailment flag (avg) | I5: Curtailment CF threshold: | J5: 0.55
B6: 0 | C6: 0 | D6: 0 | E6: 0 | F6: 0 | G6: =AVERAGE(C6:F6) | H6: =IF(G6>=Curt_Threshold,1,0)
B7: 1 | C7: 0 | D7: 0 | E7: 0 | F7: 0 | G7: =AVERAGE(C7:F7) | H7: =IF(G7>=Curt_Threshold,1,0)
B8: 2 | C8: 0 | D8: 0 | E8: 0 | F8: 0 | G8: =AVERAGE(C8:F8) | H8: =IF(G8>=Curt_Threshold,1,0)
B9: 3 | C9: 0 | D9: 0 | E9: 0 | F9: 0 | G9: =AVERAGE(C9:F9) | H9: =IF(G9>=Curt_Threshold,1,0)
B10: 4 | C10: 0 | D10: 0 | E10: 0.02 | F10: 0 | G10: =AVERAGE(C10:F10) | H10: =IF(G10>=Curt_Threshold,1,0)
B11: 5 | C11: 0 | D11: 0.02 | E11: 0.08 | F11: 0 | G11: =AVERAGE(C11:F11) | H11: =IF(G11>=Curt_Threshold,1,0)
B12: 6 | C12: 0 | D12: 0.08 | E12: 0.18 | F12: 0.02 | G12: =AVERAGE(C12:F12) | H12: =IF(G12>=Curt_Threshold,1,0)
B13: 7 | C13: 0.02 | D13: 0.18 | E13: 0.32 | F13: 0.1 | G13: =AVERAGE(C13:F13) | H13: =IF(G13>=Curt_Threshold,1,0)
B14: 8 | C14: 0.1 | D14: 0.3 | E14: 0.46 | F14: 0.22 | G14: =AVERAGE(C14:F14) | H14: =IF(G14>=Curt_Threshold,1,0)
B15: 9 | C15: 0.22 | D15: 0.45 | E15: 0.6 | F15: 0.38 | G15: =AVERAGE(C15:F15) | H15: =IF(G15>=Curt_Threshold,1,0)
B16: 10 | C16: 0.34 | D16: 0.58 | E16: 0.72 | F16: 0.52 | G16: =AVERAGE(C16:F16) | H16: =IF(G16>=Curt_Threshold,1,0)
B17: 11 | C17: 0.42 | D17: 0.68 | E17: 0.82 | F17: 0.62 | G17: =AVERAGE(C17:F17) | H17: =IF(G17>=Curt_Threshold,1,0)
... B29: 23 | C29: 0 | D29: 0 | E29: 0 | F29: 0 | G29: =AVERAGE(C29:F29) | H29: =IF(G29>=Curt_Threshold,1,0)
B31: Curtailment hours per representative day: | G31: =SUM(H6:H29)

Sheet Price_Curve
B2: Hourly spot electricity price (EUR/MWh) — European blended
B3: Midday troughs reflect oversupplied solar. Edit the yellow cells to model a specific country / year.
B5: Hour | C5: Winter €/MWh | D5: Spring €/MWh | E5: Summer €/MWh | F5: Autumn €/MWh | G5: Avg €/MWh
B6: 0 | C6: 90 | D6: 60 | E6: 35 | F6: 70 | G6: =AVERAGE(C6:F6)
B7: 1 | C7: 85 | D7: 55 | E7: 30 | F7: 65 | G7: =AVERAGE(C7:F7)
B8: 2 | C8: 80 | D8: 50 | E8: 25 | F8: 60 | G8: =AVERAGE(C8:F8)
B9: 3 | C9: 78 | D9: 48 | E9: 22 | F9: 58 | G9: =AVERAGE(C9:F9)
B10: 4 | C10: 80 | D10: 50 | E10: 25 | F10: 60 | G10: =AVERAGE(C10:F10)
B11: 5 | C11: 90 | D11: 60 | E11: 35 | F11: 70 | G11: =AVERAGE(C11:F11)
B12: 6 | C12: 110 | D12: 75 | E12: 45 | F12: 85 | G12: =AVERAGE(C12:F12)
B13: 7 | C13: 140 | D13: 90 | E13: 55 | F13: 105 | G13: =AVERAGE(C13:F13)
B14: 8 | C14: 150 | D14: 90 | E14: 45 | F14: 110 | G14: =AVERAGE(C14:F14)
B15: 9 | C15: 140 | D15: 70 | E15: 20 | F15: 95 | G15: =AVERAGE(C15:F15)
B16: 10 | C16: 120 | D16: 50 | E16: -5 | F16: 80 | G16: =AVERAGE(C16:F16)
B17: 11 | C17: 110 | D17: 35 | E17: -20 | F17: 65 | G17: =AVERAGE(C17:F17)
... B29: 23 | C29: 105 | D29: 75 | E29: 45 | F29: 85 | G29: =AVERAGE(C29:F29)
B31: Avg price | C31: =AVERAGE(C6:C29) | D31: =AVERAGE(D6:D29) | E31: =AVERAGE(E6:E29) | F31: =AVERAGE(F6:F29) | G31: =AVERAGE(G6:G29)
B32: Min price | C32: =MIN(C6:C29) | D32: =MIN(D6:D29) | E32: =MIN(E6:E29) | F32: =MIN(F6:F29) | G32: =MIN(G6:G29)
B33: Hours ≤ €0 per day | C33: =SUMPRODUCT(--(C6:C29<=0)) | D33: =SUMPRODUCT(--(D6:D29<=0)) | E33: =SUMPRODUCT(--(E6:E29<=0)) | F33: =SUMPRODUCT(--(F6:F29<=0)) | G33: =SUMPRODUCT(--(G6:G29<=0))

Sheet GPU_Economics
B2: Per-GPU economics — capex, depreciation, power, operating cost
B4: Capex stack (per GPU) | E4: Notes
B5: H100 capex | C5: =GPU_Capex | E5: Capex is the wall the model is built against — it amortises whether GPUs run or not, which is the entire pain of idle hours.
B6: Rack & networking capex | C6: =Rack_Capex
B7: Datacenter capex | C7: =DC_Capex
B8: Total capex per GPU | C8: =SUM(C5:C7) | E8: Salvage is real for H100s as long as Hopper finds a second life on inference / mid-end training.
B10: Depreciation & financing (annual)
B11: Straight-line depreciation | C11: =(Total_Capex*(1-GPU_Salvage))/GPU_Life | E11: PUE of 1.20 assumes liquid cooling at a solar-adjacent modular DC. Air-cooled colo would be ~1.45.
B12: WACC × avg invested capital | C12: =Total_Capex*WACC*0.5
B13: O&M | C13: =OandM
B14: Grid connection (allocated) | C14: =GridFee_per_kWyr*(GPU_Power_Load_W+Aux_Power_W)/1000*PUE | E14: Idle load is not zero: powered nodes still draw fans, NIC, baseboard mgmt — that's a real penalty on curtailment-only mode.
B15: Total fixed annual cost / GPU | C15: =SUM(C11:C14)
B17: Power per powered-on hour | E17: Firm vs interruptible: the curtailment-only operator cannot promise capacity, so the buyer demands a haircut.
B18: IT load (kW) | C18: =(GPU_Power_Load_W+Aux_Power_W)/1000
B19: Site load incl. PUE (kW) | C19: =C18*PUE
B20: Idle site load (kW) | C20: =(GPU_Power_Idle_W+Aux_Power_W*0.4)/1000*PUE
B22: Revenue per powered-on hour
B23: Gross revenue / hr (firm) | C23: =Rev_per_hr*Util
B24: Gross revenue / hr (interruptible / curtailment-only) | C24: =MAX(Floor_Price, Rev_per_hr*(1-Interrupt_Haircut))*Util

Sheet Scenarios
B2: Scenario comparison — three operating modes, same hardware
B3: All scenarios pay the same capex. The only variable is when we power the GPU.
C5: A. 24/7 | D5: B. Daytime-only | E5: C. Curtailment-only | F5: Comment
B6: Powered hours per year | C6: =24*365*Avail | D6: =Hrs_Daytime*365*Avail | E6: =Hrs_Curt*Curt_Days*Avail | F6: Idle hours = 8,760 - this number.
B7: Energy consumed (MWh/yr) | C7: =C6*Load_kW/1000+(8760-C6)*Idle_kW/1000 | D7: =D6*Load_kW/1000+(8760-D6)*Idle_kW/1000 | E7: =E6*Load_kW/1000+(8760-E6)*Idle_kW/1000 | F7: Idle nodes still drink power.
B8: Blended electricity price (EUR/MWh) | C8: =Grid_Price | D8: =(Grid_Price+PPA_Price)/2 | E8: =Curt_Price | F8: Curtailment scenario uses the écrêtement spot. Daytime mixes grid + PPA.
B9: Electricity cost (EUR/yr) | C9: =C7*C8 | D9: =D7*D8 | E9: =E7*E8 | F9: Negative cost is income from being paid to consume.
B10: Gross revenue (EUR/yr) | C10: =C6*Rev_Firm | D10: =D6*Rev_Firm | E10: =E6*Rev_Interr | F10: Interruptible haircut applied to scenario C.
B11: Carbon credit (EUR/yr) | C11: =0 | D11: =D7*Carbon*0.3 | E11: =E7*Carbon | F11: Curtailment-only captures the most avoidance credit per MWh.
B12: Fixed cost (depreciation, WACC, O&M) | C12: =Fixed_Cost_GPU | D12: =Fixed_Cost_GPU | E12: =Fixed_Cost_GPU | F12: Identical across scenarios — that's the whole point.
B13: EBITDA per GPU per year | C13: =C10-C9-C12+C11 | D13: =D10-D9-D12+D11 | E13: =E10-E9-E12+E11 | F13: Revenue - electricity - fixed + carbon.
B14: EBITDA margin | C14: =IFERROR(C13/C10,0) | D14: =IFERROR(D13/D10,0) | E14: =IFERROR(E13/E10,0) | F14: Sanity check.
B15: Effective LCOE on consumed power (EUR/MWh) | C15: =C9/C7 | D15: =D9/D7 | E15: =E9/E7 | F15: What we paid per MWh consumed.
B16: Revenue per consumed MWh | C16: =C10/C7 | D16: =D10/D7 | E16: =E10/E7 | F16: How efficiently we monetise the kWh.
B17: Idle hours per year | C17: =8760-C6 | D17: =8760-D6 | E17: =8760-E6 | F17: The cost of doing nothing.
B18: Cost of idle hours (depreciation share) | C18: =C17/8760*Fixed_Cost_GPU | D18: =D17/8760*Fixed_Cost_GPU | E18: =E17/8760*Fixed_Cost_GPU | F18: Allocates fixed cost pro-rata to idle hours.
B22: Verdict (per GPU per year)
B23: Best scenario: | C23: =INDEX({"24/7","Daytime","Curtailment-only"},MATCH(MAX(C13:E13),C13:E13,0))
B24: Best EBITDA / GPU / yr: | C24: =MAX(C13:E13)
B25: Margin vs. 2nd best: | C25: =LARGE(C13:E13,1)-LARGE(C13:E13,2)

Sheet Hourly_Model
B2: Hourly model — 96 representative hours, scaled to 8,760-h year
B3: Each season × 24 hours. Hours weighted to 91.25 days/season.
B5: Season | C5: Hour | D5: CF | E5: Price €/MWh | F5: Mode A on? | G5: Mode B on? | H5: Mode C on? | I5: Hour P&L A | J5: Hour P&L B | K5: Hour P&L C
B6: Winter | C6: 0 | D6: =Solar_Profile!C6 | E6: =Price_Curve!C6 | F6: =1 | G6: =IF(RANK(D6,INDIRECT("D"&(6+INT((ROW()-6)/24)*24)&":D"&(6+INT((ROW()-6)/24)*24+23)),0)<=Hrs_Daytime,1,0) | H6: =IF(RANK(D6,INDIRECT("D"&(6+INT((ROW()-6)/24)*24)&":D"&(6+INT((ROW()-6)/24)*24+23)),0)<=Hrs_Curt,1,0) | I6: =F6*(Rev_Firm - E6*Load_kW/1000) - (1-F6)*Idle_kW/1000*E6 | J6: =G6*(Rev_Firm - E6*Load_kW/1000) - (1-G6)*Idle_kW/1000*E6 | K6: =H6*(Rev_Interr - Curt_Price*Load_kW/1000) - (1-H6)*Idle_kW/1000*E6
B7: Winter | C7: 1 | D7: =Solar_Profile!C7 | E7: =Price_Curve!C7 | F7: =1 | G7: =IF(RANK(D7,INDIRECT("D"&(6+INT((ROW()-6)/24)*24)&":D"&(6+INT((ROW()-6)/24)*24+23)),0)<=Hrs_Daytime,1,0) | H7: =IF(RANK(D7,INDIRECT("D"&(6+INT((ROW()-6)/24)*24)&":D"&(6+INT((ROW()-6)/24)*24+23)),0)<=Hrs_Curt,1,0) | I7: =F7*(Rev_Firm - E7*Load_kW/1000) - (1-F7)*Idle_kW/1000*E7 | J7: =G7*(Rev_Firm - E7*Load_kW/1000) - (1-G7)*Idle_kW/1000*E7 | K7: =H7*(Rev_Interr - Curt_Price*Load_kW/1000) - (1-H7)*Idle_kW/1000*E7
B8: Winter | C8: 2 | D8: =Solar_Profile!C8 | E8: =Price_Curve!C8 | F8: =1 | G8: =IF(RANK(D8,INDIRECT("D"&(6+INT((ROW()-6)/24)*24)&":D"&(6+INT((ROW()-6)/24)*24+23)),0)<=Hrs_Daytime,1,0) | H8: =IF(RANK(D8,INDIRECT("D"&(6+INT((ROW()-6)/24)*24)&":D"&(6+INT((ROW()-6)/24)*24+23)),0)<=Hrs_Curt,1,0) | I8: =F8*(Rev_Firm - E8*Load_kW/1000) - (1-F8)*Idle_kW/1000*E8 | J8: =G8*(Rev_Firm - E8*Load_kW/1000) - (1-G8)*Idle_kW/1000*E8 | K8: =H8*(Rev_Interr - Curt_Price*Load_kW/1000) - (1-H8)*Idle_kW/1000*E8
B9: Winter | C9: 3 | D9: =Solar_Profile!C9 | E9: =Price_Curve!C9 | F9: =1 | G9: =IF(RANK(D9,INDIRECT("D"&(6+INT((ROW()-6)/24)*24)&":D"&(6+INT((ROW()-6)/24)*24+23)),0)<=Hrs_Daytime,1,0) | H9: =IF(RANK(D9,INDIRECT("D"&(6+INT((ROW()-6)/24)*24)&":D"&(6+INT((ROW()-6)/24)*24+23)),0)<=Hrs_Curt,1,0) | I9: =F9*(Rev_Firm - E9*Load_kW/1000) - (1-F9)*Idle_kW/1000*E9 | J9: =G9*(Rev_Firm - E9*Load_kW/1000) - (1-G9)*Idle_kW/1000*E9 | K9: =H9*(Rev_Interr - Curt_Price*Load_kW/1000) - (1-H9)*Idle_kW/1000*E9
B10: Winter | C10: 4 | D10: =Solar_Profile!C10 | E10: =Price_Curve!C10 | F10: =1 | G10: =IF(RANK(D10,INDIRECT("D"&(6+INT((ROW()-6)/24)*24)&":D"&(6+INT((ROW()-6)/24)*24+23)),0)<=Hrs_Daytime,1,0) | H10: =IF(RANK(D10,INDIRECT("D"&(6+INT((ROW()-6)/24)*24)&":D"&(6+INT((ROW()-6)/24)*24+23)),0)<=Hrs_Curt,1,0) | I10: =F10*(Rev_Firm - E10*Load_kW/1000) - (1-F10)*Idle_kW/1000*E10 | J10: =G10*(Rev_Firm - E10*Load_kW/1000) - (1-G10)*Idle_kW/1000*E10 | K10: =H10*(Rev_Interr - Curt_Price*Load_kW/1000) - (1-H10)*Idle_kW/1000*E10
B11: Winter | C11: 5 | D11: =Solar_Profile!C11 | E11: =Price_Curve!C11 | F11: =1 | G11: =IF(RANK(D11,INDIRECT("D"&(6+INT((ROW()-6)/24)*24)&":D"&(6+INT((ROW()-6)/24)*24+23)),0)<=Hrs_Daytime,1,0) | H11: =IF(RANK(D11,INDIRECT("D"&(6+INT((ROW()-6)/24)*24)&":D"&(6+INT((ROW()-6)/24)*24+23)),0)<=Hrs_Curt,1,0) | I11: =F11*(Rev_Firm - E11*Load_kW/1000) - (1-F11)*Idle_kW/1000*E11 | J11: =G11*(Rev_Firm - E11*Load_kW/1000) - (1-G11)*Idle_kW/1000*E11 | K11: =H11*(Rev_Interr - Curt_Price*Load_kW/1000) - (1-H11)*Idle_kW/1000*E11
B12: Winter | C12: 6 | D12: =Solar_Profile!C12 | E12: =Price_Curve!C12 | F12: =1 | G12: =IF(RANK(D12,INDIRECT("D"&(6+INT((ROW()-6)/24)*24)&":D"&(6+INT((ROW()-6)/24)*24+23)),0)<=Hrs_Daytime,1,0) | H12: =IF(RANK(D12,INDIRECT("D"&(6+INT((ROW()-6)/24)*24)&":D"&(6+INT((ROW()-6)/24)*24+23)),0)<=Hrs_Curt,1,0) | I12: =F12*(Rev_Firm - E12*Load_kW/1000) - (1-F12)*Idle_kW/1000*E12 | J12: =G12*(Rev_Firm - E12*Load_kW/1000) - (1-G12)*Idle_kW/1000*E12 | K12: =H12*(Rev_Interr - Curt_Price*Load_kW/1000) - (1-H12)*Idle_kW/1000*E12
B13: Winter | C13: 7 | D13: =Solar_Profile!C13 | E13: =Price_Curve!C13 | F13: =1 | G13: =IF(RANK(D13,INDIRECT("D"&(6+INT((ROW()-6)/24)*24)&":D"&(6+INT((ROW()-6)/24)*24+23)),0)<=Hrs_Daytime,1,0) | H13: =IF(RANK(D13,INDIRECT("D"&(6+INT((ROW()-6)/24)*24)&":D"&(6+INT((ROW()-6)/24)*24+23)),0)<=Hrs_Curt,1,0) | I13: =F13*(Rev_Firm - E13*Load_kW/1000) - (1-F13)*Idle_kW/1000*E13 | J13: =G13*(Rev_Firm - E13*Load_kW/1000) - (1-G13)*Idle_kW/1000*E13 | K13: =H13*(Rev_Interr - Curt_Price*Load_kW/1000) - (1-H13)*Idle_kW/1000*E13
B14: Winter | C14: 8 | D14: =Solar_Profile!C14 | E14: =Price_Curve!C14 | F14: =1 | G14: =IF(RANK(D14,INDIRECT("D"&(6+INT((ROW()-6)/24)*24)&":D"&(6+INT((ROW()-6)/24)*24+23)),0)<=Hrs_Daytime,1,0) | H14: =IF(RANK(D14,INDIRECT("D"&(6+INT((ROW()-6)/24)*24)&":D"&(6+INT((ROW()-6)/24)*24+23)),0)<=Hrs_Curt,1,0) | I14: =F14*(Rev_Firm - E14*Load_kW/1000) - (1-F14)*Idle_kW/1000*E14 | J14: =G14*(Rev_Firm - E14*Load_kW/1000) - (1-G14)*Idle_kW/1000*E14 | K14: =H14*(Rev_Interr - Curt_Price*Load_kW/1000) - (1-H14)*Idle_kW/1000*E14
B15: Winter | C15: 9 | D15: =Solar_Profile!C15 | E15: =Price_Curve!C15 | F15: =1 | G15: =IF(RANK(D15,INDIRECT("D"&(6+INT((ROW()-6)/24)*24)&":D"&(6+INT((ROW()-6)/24)*24+23)),0)<=Hrs_Daytime,1,0) | H15: =IF(RANK(D15,INDIRECT("D"&(6+INT((ROW()-6)/24)*24)&":D"&(6+INT((ROW()-6)/24)*24+23)),0)<=Hrs_Curt,1,0) | I15: =F15*(Rev_Firm - E15*Load_kW/1000) - (1-F15)*Idle_kW/1000*E15 | J15: =G15*(Rev_Firm - E15*Load_kW/1000) - (1-G15)*Idle_kW/1000*E15 | K15: =H15*(Rev_Interr - Curt_Price*Load_kW/1000) - (1-H15)*Idle_kW/1000*E15
B16: Winter | C16: 10 | D16: =Solar_Profile!C16 | E16: =Price_Curve!C16 | F16: =1 | G16: =IF(RANK(D16,INDIRECT("D"&(6+INT((ROW()-6)/24)*24)&":D"&(6+INT((ROW()-6)/24)*24+23)),0)<=Hrs_Daytime,1,0) | H16: =IF(RANK(D16,INDIRECT("D"&(6+INT((ROW()-6)/24)*24)&":D"&(6+INT((ROW()-6)/24)*24+23)),0)<=Hrs_Curt,1,0) | I16: =F16*(Rev_Firm - E16*Load_kW/1000) - (1-F16)*Idle_kW/1000*E16 | J16: =G16*(Rev_Firm - E16*Load_kW/1000) - (1-G16)*Idle_kW/1000*E16 | K16: =H16*(Rev_Interr - Curt_Price*Load_kW/1000) - (1-H16)*Idle_kW/1000*E16
B17: Winter | C17: 11 | D17: =Solar_Profile!C17 | E17: =Price_Curve!C17 | F17: =1 | G17: =IF(RANK(D17,INDIRECT("D"&(6+INT((ROW()-6)/24)*24)&":D"&(6+INT((ROW()-6)/24)*24+23)),0)<=Hrs_Daytime,1,0) | H17: =IF(RANK(D17,INDIRECT("D"&(6+INT((ROW()-6)/24)*24)&":D"&(6+INT((ROW()-6)/24)*24+23)),0)<=Hrs_Curt,1,0) | I17: =F17*(Rev_Firm - E17*Load_kW/1000) - (1-F17)*Idle_kW/1000*E17 | J17: =G17*(Rev_Firm - E17*Load_kW/1000) - (1-G17)*Idle_kW/1000*E17 | K17: =H17*(Rev_Interr - Curt_Price*Load_kW/1000) - (1-H17)*Idle_kW/1000*E17
... B29: Winter | C29: 23 | D29: =Solar_Profile!C29 | E29: =Price_Curve!C29 | F29: =1 | G29: =IF(RANK(D29,INDIRECT("D"&(6+INT((ROW()-6)/24)*24)&":D"&(6+INT((ROW()-6)/24)*24+23)),0)<=Hrs_Daytime,1,0) | H29: =IF(RANK(D29,INDIRECT("D"&(6+INT((ROW()-6)/24)*24)&":D"&(6+INT((ROW()-6)/24)*24+23)),0)<=Hrs_Curt,1,0) | I29: =F29*(Rev_Firm - E29*Load_kW/1000) - (1-F29)*Idle_kW/1000*E29 | J29: =G29*(Rev_Firm - E29*Load_kW/1000) - (1-G29)*Idle_kW/1000*E29 | K29: =H29*(Rev_Interr - Curt_Price*Load_kW/1000) - (1-H29)*Idle_kW/1000*E29
B30: Spring | C30: 0 | D30: =Solar_Profile!D6 | E30: =Price_Curve!D6 | F30: =1 | G30: =IF(RANK(D30,INDIRECT("D"&(6+INT((ROW()-6)/24)*24)&":D"&(6+INT((ROW()-6)/24)*24+23)),0)<=Hrs_Daytime,1,0) | H30: =IF(RANK(D30,INDIRECT("D"&(6+INT((ROW()-6)/24)*24)&":D"&(6+INT((ROW()-6)/24)*24+23)),0)<=Hrs_Curt,1,0) | I30: =F30*(Rev_Firm - E30*Load_kW/1000) - (1-F30)*Idle_kW/1000*E30 | J30: =G30*(Rev_Firm - E30*Load_kW/1000) - (1-G30)*Idle_kW/1000*E30 | K30: =H30*(Rev_Interr - Curt_Price*Load_kW/1000) - (1-H30)*Idle_kW/1000*E30
B31: Spring | C31: 1 | D31: =Solar_Profile!D7 | E31: =Price_Curve!D7 | F31: =1 | G31: =IF(RANK(D31,INDIRECT("D"&(6+INT((ROW()-6)/24)*24)&":D"&(6+INT((ROW()-6)/24)*24+23)),0)<=Hrs_Daytime,1,0) | H31: =IF(RANK(D31,INDIRECT("D"&(6+INT((ROW()-6)/24)*24)&":D"&(6+INT((ROW()-6)/24)*24+23)),0)<=Hrs_Curt,1,0) | I31: =F31*(Rev_Firm - E31*Load_kW/1000) - (1-F31)*Idle_kW/1000*E31 | J31: =G31*(Rev_Firm - E31*Load_kW/1000) - (1-G31)*Idle_kW/1000*E31 | K31: =H31*(Rev_Interr - Curt_Price*Load_kW/1000) - (1-H31)*Idle_kW/1000*E31
B32: Spring | C32: 2 | D32: =Solar_Profile!D8 | E32: =Price_Curve!D8 | F32: =1 | G32: =IF(RANK(D32,INDIRECT("D"&(6+INT((ROW()-6)/24)*24)&":D"&(6+INT((ROW()-6)/24)*24+23)),0)<=Hrs_Daytime,1,0) | H32: =IF(RANK(D32,INDIRECT("D"&(6+INT((ROW()-6)/24)*24)&":D"&(6+INT((ROW()-6)/24)*24+23)),0)<=Hrs_Curt,1,0) | I32: =F32*(Rev_Firm - E32*Load_kW/1000) - (1-F32)*Idle_kW/1000*E32 | J32: =G32*(Rev_Firm - E32*Load_kW/1000) - (1-G32)*Idle_kW/1000*E32 | K32: =H32*(Rev_Interr - Curt_Price*Load_kW/1000) - (1-H32)*Idle_kW/1000*E32
B33: Spring | C33: 3 | D33: =Solar_Profile!D9 | E33: =Price_Curve!D9 | F33: =1 | G33: =IF(RANK(D33,INDIRECT("D"&(6+INT((ROW()-6)/24)*24)&":D"&(6+INT((ROW()-6)/24)*24+23)),0)<=Hrs_Daytime,1,0) | H33: =IF(RANK(D33,INDIRECT("D"&(6+INT((ROW()-6)/24)*24)&":D"&(6+INT((ROW()-6)/24)*24+23)),0)<=Hrs_Curt,1,0) | I33: =F33*(Rev_Firm - E33*Load_kW/1000) - (1-F33)*Idle_kW/1000*E33 | J33: =G33*(Rev_Firm - E33*Load_kW/1000) - (1-G33)*Idle_kW/1000*E33 | K33: =H33*(Rev_Interr - Curt_Price*Load_kW/1000) - (1-H33)*Idle_kW/1000*E33
B34: Spring | C34: 4 | D34: =Solar_Profile!D10 | E34: =Price_Curve!D10 | F34: =1 | G34: =IF(RANK(D34,INDIRECT("D"&(6+INT((ROW()-6)/24)*24)&":D"&(6+INT((ROW()-6)/24)*24+23)),0)<=Hrs_Daytime,1,0) | H34: =IF(RANK(D34,INDIRECT("D"&(6+INT((ROW()-6)/24)*24)&":D"&(6+INT((ROW()-6)/24)*24+23)),0)<=Hrs_Curt,1,0) | I34: =F34*(Rev_Firm - E34*Load_kW/1000) - (1-F34)*Idle_kW/1000*E34 | J34: =G34*(Rev_Firm - E34*Load_kW/1000) - (1-G34)*Idle_kW/1000*E34 | K34: =H34*(Rev_Interr - Curt_Price*Load_kW/1000) - (1-H34)*Idle_kW/1000*E34
B35: Spring | C35: 5 | D35: =Solar_Profile!D11 | E35: =Price_Curve!D11 | F35: =1 | G35: =IF(RANK(D35,INDIRECT("D"&(6+INT((ROW()-6)/24)*24)&":D"&(6+INT((ROW()-6)/24)*24+23)),0)<=Hrs_Daytime,1,0) | H35: =IF(RANK(D35,INDIRECT("D"&(6+INT((ROW()-6)/24)*24)&":D"&(6+INT((ROW()-6)/24)*24+23)),0)<=Hrs_Curt,1,0) | I35: =F35*(Rev_Firm - E35*Load_kW/1000) - (1-F35)*Idle_kW/1000*E35 | J35: =G35*(Rev_Firm - E35*Load_kW/1000) - (1-G35)*Idle_kW/1000*E35 | K35: =H35*(Rev_Interr - Curt_Price*Load_kW/1000) - (1-H35)*Idle_kW/1000*E35
B36: Spring | C36: 6 | D36: =Solar_Profile!D12 | E36: =Price_Curve!D12 | F36: =1 | G36: =IF(RANK(D36,INDIRECT("D"&(6+INT((ROW()-6)/24)*24)&":D"&(6+INT((ROW()-6)/24)*24+23)),0)<=Hrs_Daytime,1,0) | H36: =IF(RANK(D36,INDIRECT("D"&(6+INT((ROW()-6)/24)*24)&":D"&(6+INT((ROW()-6)/24)*24+23)),0)<=Hrs_Curt,1,0) | I36: =F36*(Rev_Firm - E36*Load_kW/1000) - (1-F36)*Idle_kW/1000*E36 | J36: =G36*(Rev_Firm - E36*Load_kW/1000) - (1-G36)*Idle_kW/1000*E36 | K36: =H36*(Rev_Interr - Curt_Price*Load_kW/1000) - (1-H36)*Idle_kW/1000*E36
B37: Spring | C37: 7 | D37: =Solar_Profile!D13 | E37: =Price_Curve!D13 | F37: =1 | G37: =IF(RANK(D37,INDIRECT("D"&(6+INT((ROW()-6)/24)*24)&":D"&(6+INT((ROW()-6)/24)*24+23)),0)<=Hrs_Daytime,1,0) | H37: =IF(RANK(D37,INDIRECT("D"&(6+INT((ROW()-6)/24)*24)&":D"&(6+INT((ROW()-6)/24)*24+23)),0)<=Hrs_Curt,1,0) | I37: =F37*(Rev_Firm - E37*Load_kW/1000) - (1-F37)*Idle_kW/1000*E37 | J37: =G37*(Rev_Firm - E37*Load_kW/1000) - (1-G37)*Idle_kW/1000*E37 | K37: =H37*(Rev_Interr - Curt_Price*Load_kW/1000) - (1-H37)*Idle_kW/1000*E37
B38: Spring | C38: 8 | D38: =Solar_Profile!D14 | E38: =Price_Curve!D14 | F38: =1 | G38: =IF(RANK(D38,INDIRECT("D"&(6+INT((ROW()-6)/24)*24)&":D"&(6+INT((ROW()-6)/24)*24+23)),0)<=Hrs_Daytime,1,0) | H38: =IF(RANK(D38,INDIRECT("D"&(6+INT((ROW()-6)/24)*24)&":D"&(6+INT((ROW()-6)/24)*24+23)),0)<=Hrs_Curt,1,0) | I38: =F38*(Rev_Firm - E38*Load_kW/1000) - (1-F38)*Idle_kW/1000*E38 | J38: =G38*(Rev_Firm - E38*Load_kW/1000) - (1-G38)*Idle_kW/1000*E38 | K38: =H38*(Rev_Interr - Curt_Price*Load_kW/1000) - (1-H38)*Idle_kW/1000*E38
B39: Spring | C39: 9 | D39: =Solar_Profile!D15 | E39: =Price_Curve!D15 | F39: =1 | G39: =IF(RANK(D39,INDIRECT("D"&(6+INT((ROW()-6)/24)*24)&":D"&(6+INT((ROW()-6)/24)*24+23)),0)<=Hrs_Daytime,1,0) | H39: =IF(RANK(D39,INDIRECT("D"&(6+INT((ROW()-6)/24)*24)&":D"&(6+INT((ROW()-6)/24)*24+23)),0)<=Hrs_Curt,1,0) | I39: =F39*(Rev_Firm - E39*Load_kW/1000) - (1-F39)*Idle_kW/1000*E39 | J39: =G39*(Rev_Firm - E39*Load_kW/1000) - (1-G39)*Idle_kW/1000*E39 | K39: =H39*(Rev_Interr - Curt_Price*Load_kW/1000) - (1-H39)*Idle_kW/1000*E39
B40: Spring | C40: 10 | D40: =Solar_Profile!D16 | E40: =Price_Curve!D16 | F40: =1 | G40: =IF(RANK(D40,INDIRECT("D"&(6+INT((ROW()-6)/24)*24)&":D"&(6+INT((ROW()-6)/24)*24+23)),0)<=Hrs_Daytime,1,0) | H40: =IF(RANK(D40,INDIRECT("D"&(6+INT((ROW()-6)/24)*24)&":D"&(6+INT((ROW()-6)/24)*24+23)),0)<=Hrs_Curt,1,0) | I40: =F40*(Rev_Firm - E40*Load_kW/1000) - (1-F40)*Idle_kW/1000*E40 | J40: =G40*(Rev_Firm - E40*Load_kW/1000) - (1-G40)*Idle_kW/1000*E40 | K40: =H40*(Rev_Interr - Curt_Price*Load_kW/1000) - (1-H40)*Idle_kW/1000*E40
B41: Spring | C41: 11 | D41: =Solar_Profile!D17 | E41: =Price_Curve!D17 | F41: =1 | G41: =IF(RANK(D41,INDIRECT("D"&(6+INT((ROW()-6)/24)*24)&":D"&(6+INT((ROW()-6)/24)*24+23)),0)<=Hrs_Daytime,1,0) | H41: =IF(RANK(D41,INDIRECT("D"&(6+INT((ROW()-6)/24)*24)&":D"&(6+INT((ROW()-6)/24)*24+23)),0)<=Hrs_Curt,1,0) | I41: =F41*(Rev_Firm - E41*Load_kW/1000) - (1-F41)*Idle_kW/1000*E41 | J41: =G41*(Rev_Firm - E41*Load_kW/1000) - (1-G41)*Idle_kW/1000*E41 | K41: =H41*(Rev_Interr - Curt_Price*Load_kW/1000) - (1-H41)*Idle_kW/1000*E41
... B53: Spring | C53: 23 | D53: =Solar_Profile!D29 | E53: =Price_Curve!D29 | F53: =1 | G53: =IF(RANK(D53,INDIRECT("D"&(6+INT((ROW()-6)/24)*24)&":D"&(6+INT((ROW()-6)/24)*24+23)),0)<=Hrs_Daytime,1,0) | H53: =IF(RANK(D53,INDIRECT("D"&(6+INT((ROW()-6)/24)*24)&":D"&(6+INT((ROW()-6)/24)*24+23)),0)<=Hrs_Curt,1,0) | I53: =F53*(Rev_Firm - E53*Load_kW/1000) - (1-F53)*Idle_kW/1000*E53 | J53: =G53*(Rev_Firm - E53*Load_kW/1000) - (1-G53)*Idle_kW/1000*E53 | K53: =H53*(Rev_Interr - Curt_Price*Load_kW/1000) - (1-H53)*Idle_kW/1000*E53
B54: Summer | C54: 0 | D54: =Solar_Profile!E6 | E54: =Price_Curve!E6 | F54: =1 | G54: =IF(RANK(D54,INDIRECT("D"&(6+INT((ROW()-6)/24)*24)&":D"&(6+INT((ROW()-6)/24)*24+23)),0)<=Hrs_Daytime,1,0) | H54: =IF(RANK(D54,INDIRECT("D"&(6+INT((ROW()-6)/24)*24)&":D"&(6+INT((ROW()-6)/24)*24+23)),0)<=Hrs_Curt,1,0) | I54: =F54*(Rev_Firm - E54*Load_kW/1000) - (1-F54)*Idle_kW/1000*E54 | J54: =G54*(Rev_Firm - E54*Load_kW/1000) - (1-G54)*Idle_kW/1000*E54 | K54: =H54*(Rev_Interr - Curt_Price*Load_kW/1000) - (1-H54)*Idle_kW/1000*E54
B55: Summer | C55: 1 | D55: =Solar_Profile!E7 | E55: =Price_Curve!E7 | F55: =1 | G55: =IF(RANK(D55,INDIRECT("D"&(6+INT((ROW()-6)/24)*24)&":D"&(6+INT((ROW()-6)/24)*24+23)),0)<=Hrs_Daytime,1,0) | H55: =IF(RANK(D55,INDIRECT("D"&(6+INT((ROW()-6)/24)*24)&":D"&(6+INT((ROW()-6)/24)*24+23)),0)<=Hrs_Curt,1,0) | I55: =F55*(Rev_Firm - E55*Load_kW/1000) - (1-F55)*Idle_kW/1000*E55 | J55: =G55*(Rev_Firm - E55*Load_kW/1000) - (1-G55)*Idle_kW/1000*E55 | K55: =H55*(Rev_Interr - Curt_Price*Load_kW/1000) - (1-H55)*Idle_kW/1000*E55
B56: Summer | C56: 2 | D56: =Solar_Profile!E8 | E56: =Price_Curve!E8 | F56: =1 | G56: =IF(RANK(D56,INDIRECT("D"&(6+INT((ROW()-6)/24)*24)&":D"&(6+INT((ROW()-6)/24)*24+23)),0)<=Hrs_Daytime,1,0) | H56: =IF(RANK(D56,INDIRECT("D"&(6+INT((ROW()-6)/24)*24)&":D"&(6+INT((ROW()-6)/24)*24+23)),0)<=Hrs_Curt,1,0) | I56: =F56*(Rev_Firm - E56*Load_kW/1000) - (1-F56)*Idle_kW/1000*E56 | J56: =G56*(Rev_Firm - E56*Load_kW/1000) - (1-G56)*Idle_kW/1000*E56 | K56: =H56*(Rev_Interr - Curt_Price*Load_kW/1000) - (1-H56)*Idle_kW/1000*E56
B57: Summer | C57: 3 | D57: =Solar_Profile!E9 | E57: =Price_Curve!E9 | F57: =1 | G57: =IF(RANK(D57,INDIRECT("D"&(6+INT((ROW()-6)/24)*24)&":D"&(6+INT((ROW()-6)/24)*24+23)),0)<=Hrs_Daytime,1,0) | H57: =IF(RANK(D57,INDIRECT("D"&(6+INT((ROW()-6)/24)*24)&":D"&(6+INT((ROW()-6)/24)*24+23)),0)<=Hrs_Curt,1,0) | I57: =F57*(Rev_Firm - E57*Load_kW/1000) - (1-F57)*Idle_kW/1000*E57 | J57: =G57*(Rev_Firm - E57*Load_kW/1000) - (1-G57)*Idle_kW/1000*E57 | K57: =H57*(Rev_Interr - Curt_Price*Load_kW/1000) - (1-H57)*Idle_kW/1000*E57
B58: Summer | C58: 4 | D58: =Solar_Profile!E10 | E58: =Price_Curve!E10 | F58: =1 | G58: =IF(RANK(D58,INDIRECT("D"&(6+INT((ROW()-6)/24)*24)&":D"&(6+INT((ROW()-6)/24)*24+23)),0)<=Hrs_Daytime,1,0) | H58: =IF(RANK(D58,INDIRECT("D"&(6+INT((ROW()-6)/24)*24)&":D"&(6+INT((ROW()-6)/24)*24+23)),0)<=Hrs_Curt,1,0) | I58: =F58*(Rev_Firm - E58*Load_kW/1000) - (1-F58)*Idle_kW/1000*E58 | J58: =G58*(Rev_Firm - E58*Load_kW/1000) - (1-G58)*Idle_kW/1000*E58 | K58: =H58*(Rev_Interr - Curt_Price*Load_kW/1000) - (1-H58)*Idle_kW/1000*E58
B59: Summer | C59: 5 | D59: =Solar_Profile!E11 | E59: =Price_Curve!E11 | F59: =1 | G59: =IF(RANK(D59,INDIRECT("D"&(6+INT((ROW()-6)/24)*24)&":D"&(6+INT((ROW()-6)/24)*24+23)),0)<=Hrs_Daytime,1,0) | H59: =IF(RANK(D59,INDIRECT("D"&(6+INT((ROW()-6)/24)*24)&":D"&(6+INT((ROW()-6)/24)*24+23)),0)<=Hrs_Curt,1,0) | I59: =F59*(Rev_Firm - E59*Load_kW/1000) - (1-F59)*Idle_kW/1000*E59 | J59: =G59*(Rev_Firm - E59*Load_kW/1000) - (1-G59)*Idle_kW/1000*E59 | K59: =H59*(Rev_Interr - Curt_Price*Load_kW/1000) - (1-H59)*Idle_kW/1000*E59
B60: Summer | C60: 6 | D60: =Solar_Profile!E12 | E60: =Price_Curve!E12 | F60: =1 | G60: =IF(RANK(D60,INDIRECT("D"&(6+INT((ROW()-6)/24)*24)&":D"&(6+INT((ROW()-6)/24)*24+23)),0)<=Hrs_Daytime,1,0) | H60: =IF(RANK(D60,INDIRECT("D"&(6+INT((ROW()-6)/24)*24)&":D"&(6+INT((ROW()-6)/24)*24+23)),0)<=Hrs_Curt,1,0) | I60: =F60*(Rev_Firm - E60*Load_kW/1000) - (1-F60)*Idle_kW/1000*E60 | J60: =G60*(Rev_Firm - E60*Load_kW/1000) - (1-G60)*Idle_kW/1000*E60 | K60: =H60*(Rev_Interr - Curt_Price*Load_kW/1000) - (1-H60)*Idle_kW/1000*E60
B61: Summer | C61: 7 | D61: =Solar_Profile!E13 | E61: =Price_Curve!E13 | F61: =1 | G61: =IF(RANK(D61,INDIRECT("D"&(6+INT((ROW()-6)/24)*24)&":D"&(6+INT((ROW()-6)/24)*24+23)),0)<=Hrs_Daytime,1,0) | H61: =IF(RANK(D61,INDIRECT("D"&(6+INT((ROW()-6)/24)*24)&":D"&(6+INT((ROW()-6)/24)*24+23)),0)<=Hrs_Curt,1,0) | I61: =F61*(Rev_Firm - E61*Load_kW/1000) - (1-F61)*Idle_kW/1000*E61 | J61: =G61*(Rev_Firm - E61*Load_kW/1000) - (1-G61)*Idle_kW/1000*E61 | K61: =H61*(Rev_Interr - Curt_Price*Load_kW/1000) - (1-H61)*Idle_kW/1000*E61
B62: Summer | C62: 8 | D62: =Solar_Profile!E14 | E62: =Price_Curve!E14 | F62: =1 | G62: =IF(RANK(D62,INDIRECT("D"&(6+INT((ROW()-6)/24)*24)&":D"&(6+INT((ROW()-6)/24)*24+23)),0)<=Hrs_Daytime,1,0) | H62: =IF(RANK(D62,INDIRECT("D"&(6+INT((ROW()-6)/24)*24)&":D"&(6+INT((ROW()-6)/24)*24+23)),0)<=Hrs_Curt,1,0) | I62: =F62*(Rev_Firm - E62*Load_kW/1000) - (1-F62)*Idle_kW/1000*E62 | J62: =G62*(Rev_Firm - E62*Load_kW/1000) - (1-G62)*Idle_kW/1000*E62 | K62: =H62*(Rev_Interr - Curt_Price*Load_kW/1000) - (1-H62)*Idle_kW/1000*E62
B63: Summer | C63: 9 | D63: =Solar_Profile!E15 | E63: =Price_Curve!E15 | F63: =1 | G63: =IF(RANK(D63,INDIRECT("D"&(6+INT((ROW()-6)/24)*24)&":D"&(6+INT((ROW()-6)/24)*24+23)),0)<=Hrs_Daytime,1,0) | H63: =IF(RANK(D63,INDIRECT("D"&(6+INT((ROW()-6)/24)*24)&":D"&(6+INT((ROW()-6)/24)*24+23)),0)<=Hrs_Curt,1,0) | I63: =F63*(Rev_Firm - E63*Load_kW/1000) - (1-F63)*Idle_kW/1000*E63 | J63: =G63*(Rev_Firm - E63*Load_kW/1000) - (1-G63)*Idle_kW/1000*E63 | K63: =H63*(Rev_Interr - Curt_Price*Load_kW/1000) - (1-H63)*Idle_kW/1000*E63
B64: Summer | C64: 10 | D64: =Solar_Profile!E16 | E64: =Price_Curve!E16 | F64: =1 | G64: =IF(RANK(D64,INDIRECT("D"&(6+INT((ROW()-6)/24)*24)&":D"&(6+INT((ROW()-6)/24)*24+23)),0)<=Hrs_Daytime,1,0) | H64: =IF(RANK(D64,INDIRECT("D"&(6+INT((ROW()-6)/24)*24)&":D"&(6+INT((ROW()-6)/24)*24+23)),0)<=Hrs_Curt,1,0) | I64: =F64*(Rev_Firm - E64*Load_kW/1000) - (1-F64)*Idle_kW/1000*E64 | J64: =G64*(Rev_Firm - E64*Load_kW/1000) - (1-G64)*Idle_kW/1000*E64 | K64: =H64*(Rev_Interr - Curt_Price*Load_kW/1000) - (1-H64)*Idle_kW/1000*E64
...

Sheet Equilibrium
B2: Equilibrium — where do the three scenarios cross?
B3: At a given curtailment-window electricity price, what is the EBITDA / GPU / yr for each mode?
B5: Curt €/MWh | C5: EBITDA 24/7 | D5: EBITDA Daytime | E5: EBITDA Curt-only | G5: How to read
B6: -100 | C6: =24*365*Avail*Rev_Firm - (24*365*Avail*Load_kW/1000+(8760-24*365*Avail)*Idle_kW/1000)*Grid_Price - Fixed_Cost_GPU | D6: =Hrs_Daytime*365*Avail*Rev_Firm - (Hrs_Daytime*365*Avail*Load_kW/1000+(8760-Hrs_Daytime*365*Avail)*Idle_kW/1000)*((Grid_Price+PPA_Price)/2) - Fixed_Cost_GPU | E6: =Hrs_Curt*Curt_Days*Avail*Rev_Interr - (Hrs_Curt*Curt_Days*Avail*Load_kW/1000+(8760-Hrs_Curt*Curt_Days*Avail)*Idle_kW/1000)*B6 - Fixed_Cost_GPU | G6: The three columns show what each operating mode would earn at every curtailment-window electricity price (rows -100 to +100 €/MWh). The crossover is the price below which curtailment-only beats 24/7. Above that price, leaving GPUs idle most of the day stops paying for itself. The 'matches' rows below extrapolate the exact equilibrium price.
B7: -90 | C7: =24*365*Avail*Rev_Firm - (24*365*Avail*Load_kW/1000+(8760-24*365*Avail)*Idle_kW/1000)*Grid_Price - Fixed_Cost_GPU | D7: =Hrs_Daytime*365*Avail*Rev_Firm - (Hrs_Daytime*365*Avail*Load_kW/1000+(8760-Hrs_Daytime*365*Avail)*Idle_kW/1000)*((Grid_Price+PPA_Price)/2) - Fixed_Cost_GPU | E7: =Hrs_Curt*Curt_Days*Avail*Rev_Interr - (Hrs_Curt*Curt_Days*Avail*Load_kW/1000+(8760-Hrs_Curt*Curt_Days*Avail)*Idle_kW/1000)*B7 - Fixed_Cost_GPU
B8: -80 | C8: =24*365*Avail*Rev_Firm - (24*365*Avail*Load_kW/1000+(8760-24*365*Avail)*Idle_kW/1000)*Grid_Price - Fixed_Cost_GPU | D8: =Hrs_Daytime*365*Avail*Rev_Firm - (Hrs_Daytime*365*Avail*Load_kW/1000+(8760-Hrs_Daytime*365*Avail)*Idle_kW/1000)*((Grid_Price+PPA_Price)/2) - Fixed_Cost_GPU | E8: =Hrs_Curt*Curt_Days*Avail*Rev_Interr - (Hrs_Curt*Curt_Days*Avail*Load_kW/1000+(8760-Hrs_Curt*Curt_Days*Avail)*Idle_kW/1000)*B8 - Fixed_Cost_GPU
B9: -70 | C9: =24*365*Avail*Rev_Firm - (24*365*Avail*Load_kW/1000+(8760-24*365*Avail)*Idle_kW/1000)*Grid_Price - Fixed_Cost_GPU | D9: =Hrs_Daytime*365*Avail*Rev_Firm - (Hrs_Daytime*365*Avail*Load_kW/1000+(8760-Hrs_Daytime*365*Avail)*Idle_kW/1000)*((Grid_Price+PPA_Price)/2) - Fixed_Cost_GPU | E9: =Hrs_Curt*Curt_Days*Avail*Rev_Interr - (Hrs_Curt*Curt_Days*Avail*Load_kW/1000+(8760-Hrs_Curt*Curt_Days*Avail)*Idle_kW/1000)*B9 - Fixed_Cost_GPU
B10: -60 | C10: =24*365*Avail*Rev_Firm - (24*365*Avail*Load_kW/1000+(8760-24*365*Avail)*Idle_kW/1000)*Grid_Price - Fixed_Cost_GPU | D10: =Hrs_Daytime*365*Avail*Rev_Firm - (Hrs_Daytime*365*Avail*Load_kW/1000+(8760-Hrs_Daytime*365*Avail)*Idle_kW/1000)*((Grid_Price+PPA_Price)/2) - Fixed_Cost_GPU | E10: =Hrs_Curt*Curt_Days*Avail*Rev_Interr - (Hrs_Curt*Curt_Days*Avail*Load_kW/1000+(8760-Hrs_Curt*Curt_Days*Avail)*Idle_kW/1000)*B10 - Fixed_Cost_GPU
B11: -50 | C11: =24*365*Avail*Rev_Firm - (24*365*Avail*Load_kW/1000+(8760-24*365*Avail)*Idle_kW/1000)*Grid_Price - Fixed_Cost_GPU | D11: =Hrs_Daytime*365*Avail*Rev_Firm - (Hrs_Daytime*365*Avail*Load_kW/1000+(8760-Hrs_Daytime*365*Avail)*Idle_kW/1000)*((Grid_Price+PPA_Price)/2) - Fixed_Cost_GPU | E11: =Hrs_Curt*Curt_Days*Avail*Rev_Interr - (Hrs_Curt*Curt_Days*Avail*Load_kW/1000+(8760-Hrs_Curt*Curt_Days*Avail)*Idle_kW/1000)*B11 - Fixed_Cost_GPU
B12: -40 | C12: =24*365*Avail*Rev_Firm - (24*365*Avail*Load_kW/1000+(8760-24*365*Avail)*Idle_kW/1000)*Grid_Price - Fixed_Cost_GPU | D12: =Hrs_Daytime*365*Avail*Rev_Firm - (Hrs_Daytime*365*Avail*Load_kW/1000+(8760-Hrs_Daytime*365*Avail)*Idle_kW/1000)*((Grid_Price+PPA_Price)/2) - Fixed_Cost_GPU | E12: =Hrs_Curt*Curt_Days*Avail*Rev_Interr - (Hrs_Curt*Curt_Days*Avail*Load_kW/1000+(8760-Hrs_Curt*Curt_Days*Avail)*Idle_kW/1000)*B12 - Fixed_Cost_GPU
B13: -30 | C13: =24*365*Avail*Rev_Firm - (24*365*Avail*Load_kW/1000+(8760-24*365*Avail)*Idle_kW/1000)*Grid_Price - Fixed_Cost_GPU | D13: =Hrs_Daytime*365*Avail*Rev_Firm - (Hrs_Daytime*365*Avail*Load_kW/1000+(8760-Hrs_Daytime*365*Avail)*Idle_kW/1000)*((Grid_Price+PPA_Price)/2) - Fixed_Cost_GPU | E13: =Hrs_Curt*Curt_Days*Avail*Rev_Interr - (Hrs_Curt*Curt_Days*Avail*Load_kW/1000+(8760-Hrs_Curt*Curt_Days*Avail)*Idle_kW/1000)*B13 - Fixed_Cost_GPU
B14: -20 | C14: =24*365*Avail*Rev_Firm - (24*365*Avail*Load_kW/1000+(8760-24*365*Avail)*Idle_kW/1000)*Grid_Price - Fixed_Cost_GPU | D14: =Hrs_Daytime*365*Avail*Rev_Firm - (Hrs_Daytime*365*Avail*Load_kW/1000+(8760-Hrs_Daytime*365*Avail)*Idle_kW/1000)*((Grid_Price+PPA_Price)/2) - Fixed_Cost_GPU | E14: =Hrs_Curt*Curt_Days*Avail*Rev_Interr - (Hrs_Curt*Curt_Days*Avail*Load_kW/1000+(8760-Hrs_Curt*Curt_Days*Avail)*Idle_kW/1000)*B14 - Fixed_Cost_GPU
B15: -10 | C15: =24*365*Avail*Rev_Firm - (24*365*Avail*Load_kW/1000+(8760-24*365*Avail)*Idle_kW/1000)*Grid_Price - Fixed_Cost_GPU | D15: =Hrs_Daytime*365*Avail*Rev_Firm - (Hrs_Daytime*365*Avail*Load_kW/1000+(8760-Hrs_Daytime*365*Avail)*Idle_kW/1000)*((Grid_Price+PPA_Price)/2) - Fixed_Cost_GPU | E15: =Hrs_Curt*Curt_Days*Avail*Rev_Interr - (Hrs_Curt*Curt_Days*Avail*Load_kW/1000+(8760-Hrs_Curt*Curt_Days*Avail)*Idle_kW/1000)*B15 - Fixed_Cost_GPU
B16: 0 | C16: =24*365*Avail*Rev_Firm - (24*365*Avail*Load_kW/1000+(8760-24*365*Avail)*Idle_kW/1000)*Grid_Price - Fixed_Cost_GPU | D16: =Hrs_Daytime*365*Avail*Rev_Firm - (Hrs_Daytime*365*Avail*Load_kW/1000+(8760-Hrs_Daytime*365*Avail)*Idle_kW/1000)*((Grid_Price+PPA_Price)/2) - Fixed_Cost_GPU | E16: =Hrs_Curt*Curt_Days*Avail*Rev_Interr - (Hrs_Curt*Curt_Days*Avail*Load_kW/1000+(8760-Hrs_Curt*Curt_Days*Avail)*Idle_kW/1000)*B16 - Fixed_Cost_GPU
B17: 10 | C17: =24*365*Avail*Rev_Firm - (24*365*Avail*Load_kW/1000+(8760-24*365*Avail)*Idle_kW/1000)*Grid_Price - Fixed_Cost_GPU | D17: =Hrs_Daytime*365*Avail*Rev_Firm - (Hrs_Daytime*365*Avail*Load_kW/1000+(8760-Hrs_Daytime*365*Avail)*Idle_kW/1000)*((Grid_Price+PPA_Price)/2) - Fixed_Cost_GPU | E17: =Hrs_Curt*Curt_Days*Avail*Rev_Interr - (Hrs_Curt*Curt_Days*Avail*Load_kW/1000+(8760-Hrs_Curt*Curt_Days*Avail)*Idle_kW/1000)*B17 - Fixed_Cost_GPU
B18: 20 | C18: =24*365*Avail*Rev_Firm - (24*365*Avail*Load_kW/1000+(8760-24*365*Avail)*Idle_kW/1000)*Grid_Price - Fixed_Cost_GPU | D18: =Hrs_Daytime*365*Avail*Rev_Firm - (Hrs_Daytime*365*Avail*Load_kW/1000+(8760-Hrs_Daytime*365*Avail)*Idle_kW/1000)*((Grid_Price+PPA_Price)/2) - Fixed_Cost_GPU | E18: =Hrs_Curt*Curt_Days*Avail*Rev_Interr - (Hrs_Curt*Curt_Days*Avail*Load_kW/1000+(8760-Hrs_Curt*Curt_Days*Avail)*Idle_kW/1000)*B18 - Fixed_Cost_GPU
... B26: 100 | C26: =24*365*Avail*Rev_Firm - (24*365*Avail*Load_kW/1000+(8760-24*365*Avail)*Idle_kW/1000)*Grid_Price - Fixed_Cost_GPU | D26: =Hrs_Daytime*365*Avail*Rev_Firm - (Hrs_Daytime*365*Avail*Load_kW/1000+(8760-Hrs_Daytime*365*Avail)*Idle_kW/1000)*((Grid_Price+PPA_Price)/2) - Fixed_Cost_GPU | E26: =Hrs_Curt*Curt_Days*Avail*Rev_Interr - (Hrs_Curt*Curt_Days*Avail*Load_kW/1000+(8760-Hrs_Curt*Curt_Days*Avail)*Idle_kW/1000)*B26 - Fixed_Cost_GPU
B29: Curt-only matches 24/7 at curt €/MWh ≈ | E29: =IFERROR(FORECAST(0, B6:B26, INDEX(E6:E26-C6:C26,0)), "n/a")
B30: Curt-only matches Daytime at curt €/MWh ≈ | E30: =IFERROR(FORECAST(0, B6:B26, INDEX(E6:E26-D6:D26,0)), "n/a")

Sheet Sensitivity
B2: Two-way sensitivity — what swings the answer?
B3: Table 1: EBITDA / GPU / yr (curtailment-only) as a function of curt €/MWh × curtailment hours per day.
B5: Curt €/MWh ↓ \ Curt hrs/day → | C5: 2 | D5: 3 | E5: 4 | F5: 5 | G5: 6 | H5: 7 | I5: 8
B6: -60 | C6: =2*Curt_Days*Avail*Rev_Interr - (2*Curt_Days*Avail*Load_kW/1000+(8760-2*Curt_Days*Avail)*Idle_kW/1000)*-60 - Fixed_Cost_GPU | D6: =3*Curt_Days*Avail*Rev_Interr - (3*Curt_Days*Avail*Load_kW/1000+(8760-3*Curt_Days*Avail)*Idle_kW/1000)*-60 - Fixed_Cost_GPU | E6: =4*Curt_Days*Avail*Rev_Interr - (4*Curt_Days*Avail*Load_kW/1000+(8760-4*Curt_Days*Avail)*Idle_kW/1000)*-60 - Fixed_Cost_GPU | F6: =5*Curt_Days*Avail*Rev_Interr - (5*Curt_Days*Avail*Load_kW/1000+(8760-5*Curt_Days*Avail)*Idle_kW/1000)*-60 - Fixed_Cost_GPU | G6: =6*Curt_Days*Avail*Rev_Interr - (6*Curt_Days*Avail*Load_kW/1000+(8760-6*Curt_Days*Avail)*Idle_kW/1000)*-60 - Fixed_Cost_GPU | H6: =7*Curt_Days*Avail*Rev_Interr - (7*Curt_Days*Avail*Load_kW/1000+(8760-7*Curt_Days*Avail)*Idle_kW/1000)*-60 - Fixed_Cost_GPU | I6: =8*Curt_Days*Avail*Rev_Interr - (8*Curt_Days*Avail*Load_kW/1000+(8760-8*Curt_Days*Avail)*Idle_kW/1000)*-60 - Fixed_Cost_GPU
B7: -40 | C7: =2*Curt_Days*Avail*Rev_Interr - (2*Curt_Days*Avail*Load_kW/1000+(8760-2*Curt_Days*Avail)*Idle_kW/1000)*-40 - Fixed_Cost_GPU | D7: =3*Curt_Days*Avail*Rev_Interr - (3*Curt_Days*Avail*Load_kW/1000+(8760-3*Curt_Days*Avail)*Idle_kW/1000)*-40 - Fixed_Cost_GPU | E7: =4*Curt_Days*Avail*Rev_Interr - (4*Curt_Days*Avail*Load_kW/1000+(8760-4*Curt_Days*Avail)*Idle_kW/1000)*-40 - Fixed_Cost_GPU | F7: =5*Curt_Days*Avail*Rev_Interr - (5*Curt_Days*Avail*Load_kW/1000+(8760-5*Curt_Days*Avail)*Idle_kW/1000)*-40 - Fixed_Cost_GPU | G7: =6*Curt_Days*Avail*Rev_Interr - (6*Curt_Days*Avail*Load_kW/1000+(8760-6*Curt_Days*Avail)*Idle_kW/1000)*-40 - Fixed_Cost_GPU | H7: =7*Curt_Days*Avail*Rev_Interr - (7*Curt_Days*Avail*Load_kW/1000+(8760-7*Curt_Days*Avail)*Idle_kW/1000)*-40 - Fixed_Cost_GPU | I7: =8*Curt_Days*Avail*Rev_Interr - (8*Curt_Days*Avail*Load_kW/1000+(8760-8*Curt_Days*Avail)*Idle_kW/1000)*-40 - Fixed_Cost_GPU
B8: -20 | C8: =2*Curt_Days*Avail*Rev_Interr - (2*Curt_Days*Avail*Load_kW/1000+(8760-2*Curt_Days*Avail)*Idle_kW/1000)*-20 - Fixed_Cost_GPU | D8: =3*Curt_Days*Avail*Rev_Interr - (3*Curt_Days*Avail*Load_kW/1000+(8760-3*Curt_Days*Avail)*Idle_kW/1000)*-20 - Fixed_Cost_GPU | E8: =4*Curt_Days*Avail*Rev_Interr - (4*Curt_Days*Avail*Load_kW/1000+(8760-4*Curt_Days*Avail)*Idle_kW/1000)*-20 - Fixed_Cost_GPU | F8: =5*Curt_Days*Avail*Rev_Interr - (5*Curt_Days*Avail*Load_kW/1000+(8760-5*Curt_Days*Avail)*Idle_kW/1000)*-20 - Fixed_Cost_GPU | G8: =6*Curt_Days*Avail*Rev_Interr - (6*Curt_Days*Avail*Load_kW/1000+(8760-6*Curt_Days*Avail)*Idle_kW/1000)*-20 - Fixed_Cost_GPU | H8: =7*Curt_Days*Avail*Rev_Interr - (7*Curt_Days*Avail*Load_kW/1000+(8760-7*Curt_Days*Avail)*Idle_kW/1000)*-20 - Fixed_Cost_GPU | I8: =8*Curt_Days*Avail*Rev_Interr - (8*Curt_Days*Avail*Load_kW/1000+(8760-8*Curt_Days*Avail)*Idle_kW/1000)*-20 - Fixed_Cost_GPU
B9: -10 | C9: =2*Curt_Days*Avail*Rev_Interr - (2*Curt_Days*Avail*Load_kW/1000+(8760-2*Curt_Days*Avail)*Idle_kW/1000)*-10 - Fixed_Cost_GPU | D9: =3*Curt_Days*Avail*Rev_Interr - (3*Curt_Days*Avail*Load_kW/1000+(8760-3*Curt_Days*Avail)*Idle_kW/1000)*-10 - Fixed_Cost_GPU | E9: =4*Curt_Days*Avail*Rev_Interr - (4*Curt_Days*Avail*Load_kW/1000+(8760-4*Curt_Days*Avail)*Idle_kW/1000)*-10 - Fixed_Cost_GPU | F9: =5*Curt_Days*Avail*Rev_Interr - (5*Curt_Days*Avail*Load_kW/1000+(8760-5*Curt_Days*Avail)*Idle_kW/1000)*-10 - Fixed_Cost_GPU | G9: =6*Curt_Days*Avail*Rev_Interr - (6*Curt_Days*Avail*Load_kW/1000+(8760-6*Curt_Days*Avail)*Idle_kW/1000)*-10 - Fixed_Cost_GPU | H9: =7*Curt_Days*Avail*Rev_Interr - (7*Curt_Days*Avail*Load_kW/1000+(8760-7*Curt_Days*Avail)*Idle_kW/1000)*-10 - Fixed_Cost_GPU | I9: =8*Curt_Days*Avail*Rev_Interr - (8*Curt_Days*Avail*Load_kW/1000+(8760-8*Curt_Days*Avail)*Idle_kW/1000)*-10 - Fixed_Cost_GPU
B10: 0 | C10: =2*Curt_Days*Avail*Rev_Interr - (2*Curt_Days*Avail*Load_kW/1000+(8760-2*Curt_Days*Avail)*Idle_kW/1000)*0 - Fixed_Cost_GPU | D10: =3*Curt_Days*Avail*Rev_Interr - (3*Curt_Days*Avail*Load_kW/1000+(8760-3*Curt_Days*Avail)*Idle_kW/1000)*0 - Fixed_Cost_GPU | E10: =4*Curt_Days*Avail*Rev_Interr - (4*Curt_Days*Avail*Load_kW/1000+(8760-4*Curt_Days*Avail)*Idle_kW/1000)*0 - Fixed_Cost_GPU | F10: =5*Curt_Days*Avail*Rev_Interr - (5*Curt_Days*Avail*Load_kW/1000+(8760-5*Curt_Days*Avail)*Idle_kW/1000)*0 - Fixed_Cost_GPU | G10: =6*Curt_Days*Avail*Rev_Interr - (6*Curt_Days*Avail*Load_kW/1000+(8760-6*Curt_Days*Avail)*Idle_kW/1000)*0 - Fixed_Cost_GPU | H10: =7*Curt_Days*Avail*Rev_Interr - (7*Curt_Days*Avail*Load_kW/1000+(8760-7*Curt_Days*Avail)*Idle_kW/1000)*0 - Fixed_Cost_GPU | I10: =8*Curt_Days*Avail*Rev_Interr - (8*Curt_Days*Avail*Load_kW/1000+(8760-8*Curt_Days*Avail)*Idle_kW/1000)*0 - Fixed_Cost_GPU
B11: 10 | C11: =2*Curt_Days*Avail*Rev_Interr - (2*Curt_Days*Avail*Load_kW/1000+(8760-2*Curt_Days*Avail)*Idle_kW/1000)*10 - Fixed_Cost_GPU | D11: =3*Curt_Days*Avail*Rev_Interr - (3*Curt_Days*Avail*Load_kW/1000+(8760-3*Curt_Days*Avail)*Idle_kW/1000)*10 - Fixed_Cost_GPU | E11: =4*Curt_Days*Avail*Rev_Interr - (4*Curt_Days*Avail*Load_kW/1000+(8760-4*Curt_Days*Avail)*Idle_kW/1000)*10 - Fixed_Cost_GPU | F11: =5*Curt_Days*Avail*Rev_Interr - (5*Curt_Days*Avail*Load_kW/1000+(8760-5*Curt_Days*Avail)*Idle_kW/1000)*10 - Fixed_Cost_GPU | G11: =6*Curt_Days*Avail*Rev_Interr - (6*Curt_Days*Avail*Load_kW/1000+(8760-6*Curt_Days*Avail)*Idle_kW/1000)*10 - Fixed_Cost_GPU | H11: =7*Curt_Days*Avail*Rev_Interr - (7*Curt_Days*Avail*Load_kW/1000+(8760-7*Curt_Days*Avail)*Idle_kW/1000)*10 - Fixed_Cost_GPU | I11: =8*Curt_Days*Avail*Rev_Interr - (8*Curt_Days*Avail*Load_kW/1000+(8760-8*Curt_Days*Avail)*Idle_kW/1000)*10 - Fixed_Cost_GPU
B12: 20 | C12: =2*Curt_Days*Avail*Rev_Interr - (2*Curt_Days*Avail*Load_kW/1000+(8760-2*Curt_Days*Avail)*Idle_kW/1000)*20 - Fixed_Cost_GPU | D12: =3*Curt_Days*Avail*Rev_Interr - (3*Curt_Days*Avail*Load_kW/1000+(8760-3*Curt_Days*Avail)*Idle_kW/1000)*20 - Fixed_Cost_GPU | E12: =4*Curt_Days*Avail*Rev_Interr - (4*Curt_Days*Avail*Load_kW/1000+(8760-4*Curt_Days*Avail)*Idle_kW/1000)*20 - Fixed_Cost_GPU | F12: =5*Curt_Days*Avail*Rev_Interr - (5*Curt_Days*Avail*Load_kW/1000+(8760-5*Curt_Days*Avail)*Idle_kW/1000)*20 - Fixed_Cost_GPU | G12: =6*Curt_Days*Avail*Rev_Interr - (6*Curt_Days*Avail*Load_kW/1000+(8760-6*Curt_Days*Avail)*Idle_kW/1000)*20 - Fixed_Cost_GPU | H12: =7*Curt_Days*Avail*Rev_Interr - (7*Curt_Days*Avail*Load_kW/1000+(8760-7*Curt_Days*Avail)*Idle_kW/1000)*20 - Fixed_Cost_GPU | I12: =8*Curt_Days*Avail*Rev_Interr - (8*Curt_Days*Avail*Load_kW/1000+(8760-8*Curt_Days*Avail)*Idle_kW/1000)*20 - Fixed_Cost_GPU
B13: 40 | C13: =2*Curt_Days*Avail*Rev_Interr - (2*Curt_Days*Avail*Load_kW/1000+(8760-2*Curt_Days*Avail)*Idle_kW/1000)*40 - Fixed_Cost_GPU | D13: =3*Curt_Days*Avail*Rev_Interr - (3*Curt_Days*Avail*Load_kW/1000+(8760-3*Curt_Days*Avail)*Idle_kW/1000)*40 - Fixed_Cost_GPU | E13: =4*Curt_Days*Avail*Rev_Interr - (4*Curt_Days*Avail*Load_kW/1000+(8760-4*Curt_Days*Avail)*Idle_kW/1000)*40 - Fixed_Cost_GPU | F13: =5*Curt_Days*Avail*Rev_Interr - (5*Curt_Days*Avail*Load_kW/1000+(8760-5*Curt_Days*Avail)*Idle_kW/1000)*40 - Fixed_Cost_GPU | G13: =6*Curt_Days*Avail*Rev_Interr - (6*Curt_Days*Avail*Load_kW/1000+(8760-6*Curt_Days*Avail)*Idle_kW/1000)*40 - Fixed_Cost_GPU | H13: =7*Curt_Days*Avail*Rev_Interr - (7*Curt_Days*Avail*Load_kW/1000+(8760-7*Curt_Days*Avail)*Idle_kW/1000)*40 - Fixed_Cost_GPU | I13: =8*Curt_Days*Avail*Rev_Interr - (8*Curt_Days*Avail*Load_kW/1000+(8760-8*Curt_Days*Avail)*Idle_kW/1000)*40 - Fixed_Cost_GPU
B14: 60 | C14: =2*Curt_Days*Avail*Rev_Interr - (2*Curt_Days*Avail*Load_kW/1000+(8760-2*Curt_Days*Avail)*Idle_kW/1000)*60 - Fixed_Cost_GPU | D14: =3*Curt_Days*Avail*Rev_Interr - (3*Curt_Days*Avail*Load_kW/1000+(8760-3*Curt_Days*Avail)*Idle_kW/1000)*60 - Fixed_Cost_GPU | E14: =4*Curt_Days*Avail*Rev_Interr - (4*Curt_Days*Avail*Load_kW/1000+(8760-4*Curt_Days*Avail)*Idle_kW/1000)*60 - Fixed_Cost_GPU | F14: =5*Curt_Days*Avail*Rev_Interr - (5*Curt_Days*Avail*Load_kW/1000+(8760-5*Curt_Days*Avail)*Idle_kW/1000)*60 - Fixed_Cost_GPU | G14: =6*Curt_Days*Avail*Rev_Interr - (6*Curt_Days*Avail*Load_kW/1000+(8760-6*Curt_Days*Avail)*Idle_kW/1000)*60 - Fixed_Cost_GPU | H14: =7*Curt_Days*Avail*Rev_Interr - (7*Curt_Days*Avail*Load_kW/1000+(8760-7*Curt_Days*Avail)*Idle_kW/1000)*60 - Fixed_Cost_GPU | I14: =8*Curt_Days*Avail*Rev_Interr - (8*Curt_Days*Avail*Load_kW/1000+(8760-8*Curt_Days*Avail)*Idle_kW/1000)*60 - Fixed_Cost_GPU
B17: Table 2: EBITDA / GPU / yr (24/7 mode) as a function of GPU capex × realised hourly rate.
B18: Capex (k€) ↓ \ €/h → | C18: 0.8 | D18: 1.2 | E18: 1.6 | F18: 2 | G18: 2.4 | H18: 3 | I18: 3.6 | J18: 4.5
B19: 18000 | C19: =24*365*Avail*0.8*Util - (24*365*Avail*Load_kW/1000+(8760-24*365*Avail)*Idle_kW/1000)*Grid_Price - ((18000+Rack_Capex+DC_Capex)*(1-GPU_Salvage)/GPU_Life + (18000+Rack_Capex+DC_Capex)*WACC*0.5 + OandM + GridFee_per_kWyr*(GPU_Power_Load_W+Aux_Power_W)/1000*PUE) | D19: =24*365*Avail*1.2*Util - (24*365*Avail*Load_kW/1000+(8760-24*365*Avail)*Idle_kW/1000)*Grid_Price - ((18000+Rack_Capex+DC_Capex)*(1-GPU_Salvage)/GPU_Life + (18000+Rack_Capex+DC_Capex)*WACC*0.5 + OandM + GridFee_per_kWyr*(GPU_Power_Load_W+Aux_Power_W)/1000*PUE) | E19: =24*365*Avail*1.6*Util - (24*365*Avail*Load_kW/1000+(8760-24*365*Avail)*Idle_kW/1000)*Grid_Price - ((18000+Rack_Capex+DC_Capex)*(1-GPU_Salvage)/GPU_Life + (18000+Rack_Capex+DC_Capex)*WACC*0.5 + OandM + GridFee_per_kWyr*(GPU_Power_Load_W+Aux_Power_W)/1000*PUE) | F19: =24*365*Avail*2.0*Util - (24*365*Avail*Load_kW/1000+(8760-24*365*Avail)*Idle_kW/1000)*Grid_Price - ((18000+Rack_Capex+DC_Capex)*(1-GPU_Salvage)/GPU_Life + (18000+Rack_Capex+DC_Capex)*WACC*0.5 + OandM + GridFee_per_kWyr*(GPU_Power_Load_W+Aux_Power_W)/1000*PUE) | G19: =24*365*Avail*2.4*Util - (24*365*Avail*Load_kW/1000+(8760-24*365*Avail)*Idle_kW/1000)*Grid_Price - ((18000+Rack_Capex+DC_Capex)*(1-GPU_Salvage)/GPU_Life + (18000+Rack_Capex+DC_Capex)*WACC*0.5 + OandM + GridFee_per_kWyr*(GPU_Power_Load_W+Aux_Power_W)/1000*PUE) | H19: =24*365*Avail*3.0*Util - (24*365*Avail*Load_kW/1000+(8760-24*365*Avail)*Idle_kW/1000)*Grid_Price - ((18000+Rack_Capex+DC_Capex)*(1-GPU_Salvage)/GPU_Life + (18000+Rack_Capex+DC_Capex)*WACC*0.5 + OandM + GridFee_per_kWyr*(GPU_Power_Load_W+Aux_Power_W)/1000*PUE) | I19: =24*365*Avail*3.6*Util - (24*365*Avail*Load_kW/1000+(8760-24*365*Avail)*Idle_kW/1000)*Grid_Price - ((18000+Rack_Capex+DC_Capex)*(1-GPU_Salvage)/GPU_Life + (18000+Rack_Capex+DC_Capex)*WACC*0.5 + OandM + GridFee_per_kWyr*(GPU_Power_Load_W+Aux_Power_W)/1000*PUE) | J19: =24*365*Avail*4.5*Util - (24*365*Avail*Load_kW/1000+(8760-24*365*Avail)*Idle_kW/1000)*Grid_Price - ((18000+Rack_Capex+DC_Capex)*(1-GPU_Salvage)/GPU_Life + (18000+Rack_Capex+DC_Capex)*WACC*0.5 + OandM + GridFee_per_kWyr*(GPU_Power_Load_W+Aux_Power_W)/1000*PUE)
B20: 24000 | C20: =24*365*Avail*0.8*Util - (24*365*Avail*Load_kW/1000+(8760-24*365*Avail)*Idle_kW/1000)*Grid_Price - ((24000+Rack_Capex+DC_Capex)*(1-GPU_Salvage)/GPU_Life + (24000+Rack_Capex+DC_Capex)*WACC*0.5 + OandM + GridFee_per_kWyr*(GPU_Power_Load_W+Aux_Power_W)/1000*PUE) | D20: =24*365*Avail*1.2*Util - (24*365*Avail*Load_kW/1000+(8760-24*365*Avail)*Idle_kW/1000)*Grid_Price - ((24000+Rack_Capex+DC_Capex)*(1-GPU_Salvage)/GPU_Life + (24000+Rack_Capex+DC_Capex)*WACC*0.5 + OandM + GridFee_per_kWyr*(GPU_Power_Load_W+Aux_Power_W)/1000*PUE) | E20: =24*365*Avail*1.6*Util - (24*365*Avail*Load_kW/1000+(8760-24*365*Avail)*Idle_kW/1000)*Grid_Price - ((24000+Rack_Capex+DC_Capex)*(1-GPU_Salvage)/GPU_Life + (24000+Rack_Capex+DC_Capex)*WACC*0.5 + OandM + GridFee_per_kWyr*(GPU_Power_Load_W+Aux_Power_W)/1000*PUE) | F20: =24*365*Avail*2.0*Util - (24*365*Avail*Load_kW/1000+(8760-24*365*Avail)*Idle_kW/1000)*Grid_Price - ((24000+Rack_Capex+DC_Capex)*(1-GPU_Salvage)/GPU_Life + (24000+Rack_Capex+DC_Capex)*WACC*0.5 + OandM + GridFee_per_kWyr*(GPU_Power_Load_W+Aux_Power_W)/1000*PUE) | G20: =24*365*Avail*2.4*Util - (24*365*Avail*Load_kW/1000+(8760-24*365*Avail)*Idle_kW/1000)*Grid_Price - ((24000+Rack_Capex+DC_Capex)*(1-GPU_Salvage)/GPU_Life + (24000+Rack_Capex+DC_Capex)*WACC*0.5 + OandM + GridFee_per_kWyr*(GPU_Power_Load_W+Aux_Power_W)/1000*PUE) | H20: =24*365*Avail*3.0*Util - (24*365*Avail*Load_kW/1000+(8760-24*365*Avail)*Idle_kW/1000)*Grid_Price - ((24000+Rack_Capex+DC_Capex)*(1-GPU_Salvage)/GPU_Life + (24000+Rack_Capex+DC_Capex)*WACC*0.5 + OandM + GridFee_per_kWyr*(GPU_Power_Load_W+Aux_Power_W)/1000*PUE) | I20: =24*365*Avail*3.6*Util - (24*365*Avail*Load_kW/1000+(8760-24*365*Avail)*Idle_kW/1000)*Grid_Price - ((24000+Rack_Capex+DC_Capex)*(1-GPU_Salvage)/GPU_Life + (24000+Rack_Capex+DC_Capex)*WACC*0.5 + OandM + GridFee_per_kWyr*(GPU_Power_Load_W+Aux_Power_W)/1000*PUE) | J20: =24*365*Avail*4.5*Util - (24*365*Avail*Load_kW/1000+(8760-24*365*Avail)*Idle_kW/1000)*Grid_Price - ((24000+Rack_Capex+DC_Capex)*(1-GPU_Salvage)/GPU_Life + (24000+Rack_Capex+DC_Capex)*WACC*0.5 + OandM + GridFee_per_kWyr*(GPU_Power_Load_W+Aux_Power_W)/1000*PUE)
B21: 30000 | C21: =24*365*Avail*0.8*Util - (24*365*Avail*Load_kW/1000+(8760-24*365*Avail)*Idle_kW/1000)*Grid_Price - ((30000+Rack_Capex+DC_Capex)*(1-GPU_Salvage)/GPU_Life + (30000+Rack_Capex+DC_Capex)*WACC*0.5 + OandM + GridFee_per_kWyr*(GPU_Power_Load_W+Aux_Power_W)/1000*PUE) | D21: =24*365*Avail*1.2*Util - (24*365*Avail*Load_kW/1000+(8760-24*365*Avail)*Idle_kW/1000)*Grid_Price - ((30000+Rack_Capex+DC_Capex)*(1-GPU_Salvage)/GPU_Life + (30000+Rack_Capex+DC_Capex)*WACC*0.5 + OandM + GridFee_per_kWyr*(GPU_Power_Load_W+Aux_Power_W)/1000*PUE) | E21: =24*365*Avail*1.6*Util - (24*365*Avail*Load_kW/1000+(8760-24*365*Avail)*Idle_kW/1000)*Grid_Price - ((30000+Rack_Capex+DC_Capex)*(1-GPU_Salvage)/GPU_Life + (30000+Rack_Capex+DC_Capex)*WACC*0.5 + OandM + GridFee_per_kWyr*(GPU_Power_Load_W+Aux_Power_W)/1000*PUE) | F21: =24*365*Avail*2.0*Util - (24*365*Avail*Load_kW/1000+(8760-24*365*Avail)*Idle_kW/1000)*Grid_Price - ((30000+Rack_Capex+DC_Capex)*(1-GPU_Salvage)/GPU_Life + (30000+Rack_Capex+DC_Capex)*WACC*0.5 + OandM + GridFee_per_kWyr*(GPU_Power_Load_W+Aux_Power_W)/1000*PUE) | G21: =24*365*Avail*2.4*Util - (24*365*Avail*Load_kW/1000+(8760-24*365*Avail)*Idle_kW/1000)*Grid_Price - ((30000+Rack_Capex+DC_Capex)*(1-GPU_Salvage)/GPU_Life + (30000+Rack_Capex+DC_Capex)*WACC*0.5 + OandM + GridFee_per_kWyr*(GPU_Power_Load_W+Aux_Power_W)/1000*PUE) | H21: =24*365*Avail*3.0*Util - (24*365*Avail*Load_kW/1000+(8760-24*365*Avail)*Idle_kW/1000)*Grid_Price - ((30000+Rack_Capex+DC_Capex)*(1-GPU_Salvage)/GPU_Life + (30000+Rack_Capex+DC_Capex)*WACC*0.5 + OandM + GridFee_per_kWyr*(GPU_Power_Load_W+Aux_Power_W)/1000*PUE) | I21: =24*365*Avail*3.6*Util - (24*365*Avail*Load_kW/1000+(8760-24*365*Avail)*Idle_kW/1000)*Grid_Price - ((30000+Rack_Capex+DC_Capex)*(1-GPU_Salvage)/GPU_Life + (30000+Rack_Capex+DC_Capex)*WACC*0.5 + OandM + GridFee_per_kWyr*(GPU_Power_Load_W+Aux_Power_W)/1000*PUE) | J21: =24*365*Avail*4.5*Util - (24*365*Avail*Load_kW/1000+(8760-24*365*Avail)*Idle_kW/1000)*Grid_Price - ((30000+Rack_Capex+DC_Capex)*(1-GPU_Salvage)/GPU_Life + (30000+Rack_Capex+DC_Capex)*WACC*0.5 + OandM + GridFee_per_kWyr*(GPU_Power_Load_W+Aux_Power_W)/1000*PUE)
B22: 36000 | C22: =24*365*Avail*0.8*Util - (24*365*Avail*Load_kW/1000+(8760-24*365*Avail)*Idle_kW/1000)*Grid_Price - ((36000+Rack_Capex+DC_Capex)*(1-GPU_Salvage)/GPU_Life + (36000+Rack_Capex+DC_Capex)*WACC*0.5 + OandM + GridFee_per_kWyr*(GPU_Power_Load_W+Aux_Power_W)/1000*PUE) | D22: =24*365*Avail*1.2*Util - (24*365*Avail*Load_kW/1000+(8760-24*365*Avail)*Idle_kW/1000)*Grid_Price - ((36000+Rack_Capex+DC_Capex)*(1-GPU_Salvage)/GPU_Life + (36000+Rack_Capex+DC_Capex)*WACC*0.5 + OandM + GridFee_per_kWyr*(GPU_Power_Load_W+Aux_Power_W)/1000*PUE) | E22: =24*365*Avail*1.6*Util - (24*365*Avail*Load_kW/1000+(8760-24*365*Avail)*Idle_kW/1000)*Grid_Price - ((36000+Rack_Capex+DC_Capex)*(1-GPU_Salvage)/GPU_Life + (36000+Rack_Capex+DC_Capex)*WACC*0.5 + OandM + GridFee_per_kWyr*(GPU_Power_Load_W+Aux_Power_W)/1000*PUE) | F22: =24*365*Avail*2.0*Util - (24*365*Avail*Load_kW/1000+(8760-24*365*Avail)*Idle_kW/1000)*Grid_Price - ((36000+Rack_Capex+DC_Capex)*(1-GPU_Salvage)/GPU_Life + (36000+Rack_Capex+DC_Capex)*WACC*0.5 + OandM + GridFee_per_kWyr*(GPU_Power_Load_W+Aux_Power_W)/1000*PUE) | G22: =24*365*Avail*2.4*Util - (24*365*Avail*Load_kW/1000+(8760-24*365*Avail)*Idle_kW/1000)*Grid_Price - ((36000+Rack_Capex+DC_Capex)*(1-GPU_Salvage)/GPU_Life + (36000+Rack_Capex+DC_Capex)*WACC*0.5 + OandM + GridFee_per_kWyr*(GPU_Power_Load_W+Aux_Power_W)/1000*PUE) | H22: =24*365*Avail*3.0*Util - (24*365*Avail*Load_kW/1000+(8760-24*365*Avail)*Idle_kW/1000)*Grid_Price - ((36000+Rack_Capex+DC_Capex)*(1-GPU_Salvage)/GPU_Life + (36000+Rack_Capex+DC_Capex)*WACC*0.5 + OandM + GridFee_per_kWyr*(GPU_Power_Load_W+Aux_Power_W)/1000*PUE) | I22: =24*365*Avail*3.6*Util - (24*365*Avail*Load_kW/1000+(8760-24*365*Avail)*Idle_kW/1000)*Grid_Price - ((36000+Rack_Capex+DC_Capex)*(1-GPU_Salvage)/GPU_Life + (36000+Rack_Capex+DC_Capex)*WACC*0.5 + OandM + GridFee_per_kWyr*(GPU_Power_Load_W+Aux_Power_W)/1000*PUE) | J22: =24*365*Avail*4.5*Util - (24*365*Avail*Load_kW/1000+(8760-24*365*Avail)*Idle_kW/1000)*Grid_Price - ((36000+Rack_Capex+DC_Capex)*(1-GPU_Salvage)/GPU_Life + (36000+Rack_Capex+DC_Capex)*WACC*0.5 + OandM + GridFee_per_kWyr*(GPU_Power_Load_W+Aux_Power_W)/1000*PUE)
